Workbook

Sheet Overview
B2: Amazon Sales Dataset — Analysis & Dashboard
B3: End-to-end Excel project: data cleaning, KPI calculation, and visual dashboard
B6: Source data | C6: 1,465 Amazon.in product listings (Raw_Data sheet) — name, category, prices, discount %, rating, review count.
B8: Data cleaning | C8: Clean_Data sheet converts currency text (₹, commas) and percentages into real numbers using formulas, and extracts Brand and top-level Category.
B10: Brand_Summary | C10: Aggregated metrics (avg price, avg discount, avg rating, total reviews) for the 10 most-reviewed brands, built with AVERAGEIF / SUMIF / COUNTIF.
B12: Category_Summary | C12: Same aggregation rolled up by top-level product category.
B14: Top_Products | C14: Top 15 products ranked by review volume and by discount %, pulled dynamically with LARGE + INDEX/MATCH.
B16: Dashboard | C16: KPI cards plus 8 charts (combo, clustered bar, radar, scatter, area, pie, doughnut, ranked bar) summarizing pricing and review patterns.
B18: How to refresh | C18: Paste new rows into Raw_Data — every formula, summary table and chart recalculates automatically.

Sheet Raw_Data
A1: Product Name | B1: Category (Full Path) | C1: Discounted Price (raw) | D1: Actual Price (raw) | E1: Discount % (raw) | F1: Rating (raw) | G1: Rating Count (raw)
A2: Wayona Nylon Braided USB to Lightning Fast Charging and Data Sync Cable Compatible for iPhone 13, 12,11, X, 8, 7, 6, 5, iPad Air, Pro, Mini (3 FT Pack of 1, Grey) | B2: Computers&Accessories|Accessories&Peripherals|Cables&Accessories|Cables|USBCables | C2: ₹399 | D2: ₹1,099 | E2: 64% | F2: 4.2 | G2: 24,269
A3: Ambrane Unbreakable 60W / 3A Fast Charging 1.5m Braided Type C Cable for Smartphones, Tablets, Laptops & other Type C devices, PD Technology, 480Mbps Data Sync, Quick Charge 3.0 (RCT15A, Black) | B3: Computers&Accessories|Accessories&Peripherals|Cables&Accessories|Cables|USBCables | C3: ₹199 | D3: ₹349 | E3: 43% | F3: 4.0 | G3: 43,994
A4: Sounce Fast Phone Charging Cable & Data Sync USB Cable Compatible for iPhone 13, 12,11, X, 8, 7, 6, 5, iPad Air, Pro, Mini & iOS Devices | B4: Computers&Accessories|Accessories&Peripherals|Cables&Accessories|Cables|USBCables | C4: ₹199 | D4: ₹1,899 | E4: 90% | F4: 3.9 | G4: 7,928
A5: boAt Deuce USB 300 2 in 1 Type-C & Micro USB Stress Resistant, Tangle-Free, Sturdy Cable with 3A Fast Charging & 480mbps Data Transmission, 10000+ Bends Lifespan and Extended 1.5m Length(Martian Red) | B5: Computers&Accessories|Accessories&Peripherals|Cables&Accessories|Cables|USBCables | C5: ₹329 | D5: ₹699 | E5: 53% | F5: 4.2 | G5: 94,363
A6: Portronics Konnect L 1.2M Fast Charging 3A 8 Pin USB Cable with Charge & Sync Function for iPhone, iPad (Grey) | B6: Computers&Accessories|Accessories&Peripherals|Cables&Accessories|Cables|USBCables | C6: ₹154 | D6: ₹399 | E6: 61% | F6: 4.2 | G6: 16,905
A7: pTron Solero TB301 3A Type-C Data and Fast Charging Cable, Made in India, 480Mbps Data Sync, Strong and Durable 1.5-Meter Nylon Braided USB Cable for Type-C Devices for Charging Adapter (Black) | B7: Computers&Accessories|Accessories&Peripherals|Cables&Accessories|Cables|USBCables | C7: ₹149 | D7: ₹1,000 | E7: 85% | F7: 3.9 | G7: 24,871
A8: boAt Micro USB 55 Tangle-free, Sturdy Micro USB Cable with 3A Fast Charging & 480mbps Data Transmission (Black) | B8: Computers&Accessories|Accessories&Peripherals|Cables&Accessories|Cables|USBCables | C8: ₹176.63 | D8: ₹499 | E8: 65% | F8: 4.1 | G8: 15,188
A9: MI Usb Type-C Cable Smartphone (Black) | B9: Computers&Accessories|Accessories&Peripherals|Cables&Accessories|Cables|USBCables | C9: ₹229 | D9: ₹299 | E9: 23% | F9: 4.3 | G9: 30,411
A10: TP-Link USB WiFi Adapter for PC(TL-WN725N), N150 Wireless Network Adapter for Desktop - Nano Size WiFi Dongle Compatible with Windows 11/10/7/8/8.1/XP/ Mac OS 10.9-10.15 Linux Kernel 2.6.18-4.4.3 | B10: Computers&Accessories|NetworkingDevices|NetworkAdapters|WirelessUSBAdapters | C10: ₹499 | D10: ₹999 | E10: 50% | F10: 4.2 | G10: 1,79,691
A11: Ambrane Unbreakable 60W / 3A Fast Charging 1.5m Braided Micro USB Cable for Smartphones, Tablets, Laptops & Other Micro USB Devices, 480Mbps Data Sync, Quick Charge 3.0 (RCM15, Black) | B11: Computers&Accessories|Accessories&Peripherals|Cables&Accessories|Cables|USBCables | C11: ₹199 | D11: ₹299 | E11: 33% | F11: 4.0 | G11: 43,994
A12: Portronics Konnect L POR-1081 Fast Charging 3A Type-C Cable 1.2Meter with Charge & Sync Function for All Type-C Devices (Grey) | B12: Computers&Accessories|Accessories&Peripherals|Cables&Accessories|Cables|USBCables | C12: ₹154 | D12: ₹339 | E12: 55% | F12: 4.3 | G12: 13,391
... A283: Lenovo USB A to Type-C Tangle-free Aramid fiber braided 1.2m cable with 4A Fast charging & 480 MBPS data transmission, certified 10000+ bend lifespan, Metallic Grey | B283: Computers&Accessories|Accessories&Peripherals|Cables&Accessories|Cables|USBCables | C283: ₹417.44 | D283: ₹670 | E283: 38% | F283: 3.9 | G283: 523
A284: Amazon Brand - Solimo 65W Fast Charging Braided Type C to C Data Cable | Suitable For All Supported Mobile Phones (1 Meter, Black) | B284: Computers&Accessories|Accessories&Peripherals|Cables&Accessories|Cables|USBCables | C284: ₹199 | D284: ₹999 | E284: 80% | F284: 3.0
A285: LG 139 cm (55 inches) 4K Ultra HD Smart LED TV 55UQ7500PSF (Ceramic Black) | B285: Electronics|HomeTheater,TV&Video|Televisions|SmartTelevisions | C285: ₹47,990 | D285: ₹79,990 | E285: 40% | F285: 4.3 | G285: 1,376
A286: Tata Sky Digital TV HD Setup Box Remote | B286: Electronics|HomeTheater,TV&Video|Accessories|RemoteControls | C286: ₹215 | D286: ₹499 | E286: 57% | F286: 3.5 | G286: 121
A287: pTron Solero T241 2.4A Type-C Data & Charging USB Cable, Made in India, 480Mbps Data Sync, Durable 1-Meter Long USB Cable for Smartphone, Type-C USB Devices (White) | B287: Computers&Accessories|Accessories&Peripherals|Cables&Accessories|Cables|USBCables | C287: ₹99 | D287: ₹800 | E287: 88% | F287: 3.9 | G287: 1,075
A288: VU 108 cm (43 inches) Premium Series Full HD Smart LED TV 43GA (Black) | B288: Electronics|HomeTheater,TV&Video|Televisions|SmartTelevisions | C288: ₹18,999 | D288: ₹35,000 | E288: 46% | F288: 4.0 | G288: 1,001
A289: Storite Super Speed USB 3.0 Male to Male Cable for Hard Drive Enclosures, Laptop Cooling Pad, DVD Players(60cm,Black) | B289: Computers&Accessories|Accessories&Peripherals|Cables&Accessories|Cables|USBCables | C289: ₹249 | D289: ₹999 | E289: 75% | F289: 4.3 | G289: 112
A290: Kodak 80 cm (32 Inches) HD Ready LED TV Kodak 32HDX900S (Black) | B290: Electronics|HomeTheater,TV&Video|Televisions|StandardTelevisions | C290: ₹7,999 | D290: ₹15,999 | E290: 50% | F290: 3.8 | G290: 3,022
A291: AmazonBasics Double Braided Nylon USB Type-C to Type-C 2.0 Cable, Charging Adapter, Smartphone 6 feet, Dark Grey | B291: Computers&Accessories|Accessories&Peripherals|Cables&Accessories|Cables|USBCables | C291: ₹649 | D291: ₹1,600 | E291: 59% | F291: 4.3 | G291: 5,451
A292: Firestick Remote | B292: Electronics|HomeTheater,TV&Video|Accessories|RemoteControls | C292: ₹1,289 | D292: ₹2,499 | E292: 48% | F292: 3.3 | G292: 73
A293: AmazonBasics 10.2 Gbps High-Speed 4K HDMI Cable with Braided Cord (10-Foot, Dark Grey) | B293: Electronics|HomeTheater,TV&Video|Accessories|Cables|HDMICables | C293: ₹609 | D293: ₹1,500 | E293: 59% | F293: 4.5 | G293: 1,029
A294: Hisense 126 cm (50 inches) Bezelless Series 4K Ultra HD Smart LED Google TV 50A6H (Black) | B294: Electronics|HomeTheater,TV&Video|Televisions|SmartTelevisions | C294: ₹32,990 | D294: ₹54,990 | E294: 40% | F294: 4.1 | G294: 1,555
A295: Tuarso 8K HDMI 2.1 Cable 48Gbps , 1.5 Meter High-Speed Braided HDMI Cable ( 8K@60HZ、4K@120HZ、2K@240HZ ) HDMI 2.1 Cable Compatible with Monitors , Television , Laptops , Projectors , Game Consoles and more with HDMI Ports Device | B295: Electronics|HomeTheater,TV&Video|Accessories|Cables|HDMICables | C295: ₹599 | D295: ₹1,999 | E295: 70% | F295: 4.2 | G295: 47
A296: AmazonBasics USB Type-C to Micro-B 2.0 Cable - 6 Inches (15.2 Centimeters) - White | B296: Computers&Accessories|Accessories&Peripherals|Cables&Accessories|Cables|USBCables | C296: ₹349 | D296: ₹899 | E296: 61% | F296: 4.1 | G296: 14,896
... A325: TCL 108 cm (43 inches) 4K Ultra HD Certified Android Smart LED TV 43P615 (Black) | B325: Electronics|HomeTheater,TV&Video|Televisions|SmartTelevisions | C325: ₹24,990 | D325: ₹51,990 | E325: 52% | F325: 4.2 | G325: 2,951
A326: REDTECH USB-C to Lightning Cable 3.3FT, [Apple MFi Certified] Lightning to Type C Fast Charging Cord Compatible with iPhone 14/13/13 pro/Max/12/11/X/XS/XR/8, Supports Power Delivery - White | B326: Computers&Accessories|Accessories&Peripherals|Cables&Accessories|Cables|USBCables | C326: ₹249 | D326: ₹999 | E326: 75% | F326: 5.0
A327: OnePlus 163.8 cm (65 inches) U Series 4K LED Smart Android TV 65U1S (Black) | B327: Electronics|HomeTheater,TV&Video|Televisions|SmartTelevisions | C327: ₹61,999 | D327: ₹69,999 | E327: 11% | F327: 4.1 | G327: 6,753
A328: AmazonBasics 108 cm (43 inches) 4K Ultra HD Smart LED Fire TV AB43U20PS (Black) | B328: Electronics|HomeTheater,TV&Video|Televisions|SmartTelevisions | C328: ₹24,499 | D328: ₹50,000 | E328: 51% | F328: 3.9 | G328: 3,518
A329: Kodak 80 cm (32 inches) HD Ready Certified Android Smart LED TV 32HDX7XPROBL (Black) | B329: Electronics|HomeTheater,TV&Video|Televisions|SmartTelevisions | C329: ₹10,499 | D329: ₹19,499 | E329: 46% | F329: 4.2 | G329: 1,510
A330: Synqe Type C to Type C Short Fast Charging 60W Cable Compatible with Samsung Galaxy Z Fold3 5G, Z Flip3 5G, S22 5G, S22 Ultra, S21, S20, S20FE, A52, A73, A53 (0.25M, Black) | B330: Computers&Accessories|Accessories&Peripherals|Cables&Accessories|Cables|USBCables | C330: ₹349 | D330: ₹999 | E330: 65% | F330: 4.3 | G330: 838
A331: Airtel DigitalTV HD Setup Box Remote | B331: Electronics|HomeTheater,TV&Video|Accessories|RemoteControls | C331: ₹197 | D331: ₹499 | E331: 61% | F331: 3.8 | G331: 136
A332: Airtel Digital TV HD Set Top Box with FTA Pack | Unlimited Entertainment + Recording Feature + Free Standard Installation (6 Months Pack) | B332: Electronics|HomeTheater,TV&Video|SatelliteEquipment|SatelliteReceivers | C332: ₹1,299 | D332: ₹2,499 | E332: 48% | F332: 4.3 | G332: 301
A333: ESR USB C to Lightning Cable, 10 ft (3 m), MFi-Certified, Braided Nylon Power Delivery Fast Charging for iPhone 14/14 Plus/14 Pro/14 Pro Max, iPhone 13/12/11/X/8 Series, Use with Type-C Chargers, Black | B333: Computers&Accessories|Accessories&Peripherals|Cables&Accessories|Cables|USBCables | C333: ₹1,519 | D333: ₹1,899 | E333: 20% | F333: 4.4 | G333: 19,763
A334: MI 138.8 cm (55 inches) 5X Series 4K Ultra HD LED Smart Android TV L55M6-ES (Grey) | B334: Electronics|HomeTheater,TV&Video|Televisions|SmartTelevisions | C334: ₹46,999 | D334: ₹69,999 | E334: 33% | F334: 4.3 | G334: 21,252
A335: Storite USB Extension Cable USB 3.0 Male to Female Extension Cable High Speed 5GBps Extension Cable Data Transfer for Keyboard, Mouse, Flash Drive, Hard Drive, Printer and More- 1.5M - Blue | B335: Computers&Accessories|Accessories&Peripherals|Cables&Accessories|Cables|USBCables | C335: ₹299 | D335: ₹799 | E335: 63% | F335: 4.3 | G335: 1,902
A336: Fire-Boltt Ninja Call Pro Plus 1.83" Smart Watch with Bluetooth Calling, AI Voice Assistance, 100 Sports Modes IP67 Rating, 240*280 Pixel High Resolution | B336: Electronics|WearableTechnology|SmartWatches | C336: ₹1,799 | D336: ₹19,999 | E336: 91% | F336: 4.2 | G336: 13,937
A337: Fire-Boltt Phoenix Smart Watch with Bluetooth Calling 1.3",120+ Sports Modes, 240*240 PX High Res with SpO2, Heart Rate Monitoring & IP67 Rating | B337: Electronics|WearableTechnology|SmartWatches | C337: ₹1,998 | D337: ₹9,999 | E337: 80% | F337: 4.3 | G337: 27,696
A338: boAt Wave Call Smart Watch, Smart Talk with Advanced Dedicated Bluetooth Calling Chip, 1.69” HD Display with 550 NITS & 70% Color Gamut, 150+ Watch Faces, Multi-Sport Modes,HR,SpO2, IP68(Active Black) | B338: Electronics|WearableTechnology|SmartWatches | C338: ₹1,999 | D338: ₹7,990 | E338: 75% | F338: 3.8 | G338: 17,831
...

Sheet Clean_Data
A1: Product Name | B1: Brand | C1: Category | D1: Discounted Price | E1: Actual Price | F1: Discount % | G1: Rating | H1: Rating Count | I1: Savings (₹) | J1: Revenue Proxy (₹) | K1: RatingCount Rank Key | L1: Discount% Rank Key
A2: =Raw_Data!A2 -> Wayona Nylon Braided USB to Lightning Fast Charging and Data Sync Cable Compatible for iPhone 13, 12,11, X, 8, 7, 6, 5, iPad Air, Pro, Mini (3 FT Pack of 1, Grey) | B2: =IFERROR(TRIM(LEFT(Raw_Data!A2,FIND(" ",Raw_Data!A2)-1)),Raw_Data!A2) -> Wayona | C2: =IFERROR(LEFT(Raw_Data!B2,FIND("|",Raw_Data!B2)-1),Raw_Data!B2) -> Computers&Accessories | D2: =IFERROR(VALUE(SUBSTITUTE(SUBSTITUTE(TRIM(Raw_Data!C2),"₹",""),",","")),"") -> 399 | E2: =IFERROR(VALUE(SUBSTITUTE(SUBSTITUTE(TRIM(Raw_Data!D2),"₹",""),",","")),"") -> 1099 | F2: =IFERROR(VALUE(SUBSTITUTE(Raw_Data!E2,"%",""))/100,"") -> 0.64 | G2: =IFERROR(VALUE(Raw_Data!F2),"") -> 4.2 | H2: =IFERROR(VALUE(SUBSTITUTE(Raw_Data!G2,",","")),"") -> 24269 | I2: =IFERROR(E2-D2,"") -> 700 | J2: =IFERROR(D2*H2,"") -> 9683331 | K2: =IF(ISNUMBER(H2),H2+ROW()/10000000,"") -> 24269 | L2: =IF(ISNUMBER(F2),F2+ROW()/10000000,"") -> 0.6400002
A3: =Raw_Data!A3 -> Ambrane Unbreakable 60W / 3A Fast Charging 1.5m Braided Type C Cable for Smartphones, Tablets, Laptops & other Type C devices, PD Technology, 480Mbps Data Sync, Quick Charge 3.0 (RCT15A, Black) | B3: =IFERROR(TRIM(LEFT(Raw_Data!A3,FIND(" ",Raw_Data!A3)-1)),Raw_Data!A3) -> Ambrane | C3: =IFERROR(LEFT(Raw_Data!B3,FIND("|",Raw_Data!B3)-1),Raw_Data!B3) -> Computers&Accessories | D3: =IFERROR(VALUE(SUBSTITUTE(SUBSTITUTE(TRIM(Raw_Data!C3),"₹",""),",","")),"") -> 199 | E3: =IFERROR(VALUE(SUBSTITUTE(SUBSTITUTE(TRIM(Raw_Data!D3),"₹",""),",","")),"") -> 349 | F3: =IFERROR(VALUE(SUBSTITUTE(Raw_Data!E3,"%",""))/100,"") -> 0.43 | G3: =IFERROR(VALUE(Raw_Data!F3),"") -> 4 | H3: =IFERROR(VALUE(SUBSTITUTE(Raw_Data!G3,",","")),"") -> 43994 | I3: =IFERROR(E3-D3,"") -> 150 | J3: =IFERROR(D3*H3,"") -> 8754806 | K3: =IF(ISNUMBER(H3),H3+ROW()/10000000,"") -> 43994 | L3: =IF(ISNUMBER(F3),F3+ROW()/10000000,"") -> 0.4300003
A4: =Raw_Data!A4 -> Sounce Fast Phone Charging Cable & Data Sync USB Cable Compatible for iPhone 13, 12,11, X, 8, 7, 6, 5, iPad Air, Pro, Mini & iOS Devices | B4: =IFERROR(TRIM(LEFT(Raw_Data!A4,FIND(" ",Raw_Data!A4)-1)),Raw_Data!A4) -> Sounce | C4: =IFERROR(LEFT(Raw_Data!B4,FIND("|",Raw_Data!B4)-1),Raw_Data!B4) -> Computers&Accessories | D4: =IFERROR(VALUE(SUBSTITUTE(SUBSTITUTE(TRIM(Raw_Data!C4),"₹",""),",","")),"") -> 199 | E4: =IFERROR(VALUE(SUBSTITUTE(SUBSTITUTE(TRIM(Raw_Data!D4),"₹",""),",","")),"") -> 1899 | F4: =IFERROR(VALUE(SUBSTITUTE(Raw_Data!E4,"%",""))/100,"") -> 0.9 | G4: =IFERROR(VALUE(Raw_Data!F4),"") -> 3.9 | H4: =IFERROR(VALUE(SUBSTITUTE(Raw_Data!G4,",","")),"") -> 7928 | I4: =IFERROR(E4-D4,"") -> 1700 | J4: =IFERROR(D4*H4,"") -> 1577672 | K4: =IF(ISNUMBER(H4),H4+ROW()/10000000,"") -> 7928 | L4: =IF(ISNUMBER(F4),F4+ROW()/10000000,"") -> 0.9000004
A5: =Raw_Data!A5 -> boAt Deuce USB 300 2 in 1 Type-C & Micro USB Stress Resistant, Tangle-Free, Sturdy Cable with 3A Fast Charging & 480mbps Data Transmission, 10000+ Bends Lifespan and Extended 1.5m Length(Martian Red) | B5: =IFERROR(TRIM(LEFT(Raw_Data!A5,FIND(" ",Raw_Data!A5)-1)),Raw_Data!A5) -> boAt | C5: =IFERROR(LEFT(Raw_Data!B5,FIND("|",Raw_Data!B5)-1),Raw_Data!B5) -> Computers&Accessories | D5: =IFERROR(VALUE(SUBSTITUTE(SUBSTITUTE(TRIM(Raw_Data!C5),"₹",""),",","")),"") -> 329 | E5: =IFERROR(VALUE(SUBSTITUTE(SUBSTITUTE(TRIM(Raw_Data!D5),"₹",""),",","")),"") -> 699 | F5: =IFERROR(VALUE(SUBSTITUTE(Raw_Data!E5,"%",""))/100,"") -> 0.53 | G5: =IFERROR(VALUE(Raw_Data!F5),"") -> 4.2 | H5: =IFERROR(VALUE(SUBSTITUTE(Raw_Data!G5,",","")),"") -> 94363 | I5: =IFERROR(E5-D5,"") -> 370 | J5: =IFERROR(D5*H5,"") -> 31045427 | K5: =IF(ISNUMBER(H5),H5+ROW()/10000000,"") -> 94363 | L5: =IF(ISNUMBER(F5),F5+ROW()/10000000,"") -> 0.5300005
A6: =Raw_Data!A6 -> Portronics Konnect L 1.2M Fast Charging 3A 8 Pin USB Cable with Charge & Sync Function for iPhone, iPad (Grey) | B6: =IFERROR(TRIM(LEFT(Raw_Data!A6,FIND(" ",Raw_Data!A6)-1)),Raw_Data!A6) -> Portronics | C6: =IFERROR(LEFT(Raw_Data!B6,FIND("|",Raw_Data!B6)-1),Raw_Data!B6) -> Computers&Accessories | D6: =IFERROR(VALUE(SUBSTITUTE(SUBSTITUTE(TRIM(Raw_Data!C6),"₹",""),",","")),"") -> 154 | E6: =IFERROR(VALUE(SUBSTITUTE(SUBSTITUTE(TRIM(Raw_Data!D6),"₹",""),",","")),"") -> 399 | F6: =IFERROR(VALUE(SUBSTITUTE(Raw_Data!E6,"%",""))/100,"") -> 0.61 | G6: =IFERROR(VALUE(Raw_Data!F6),"") -> 4.2 | H6: =IFERROR(VALUE(SUBSTITUTE(Raw_Data!G6,",","")),"") -> 16905 | I6: =IFERROR(E6-D6,"") -> 245 | J6: =IFERROR(D6*H6,"") -> 2603370 | K6: =IF(ISNUMBER(H6),H6+ROW()/10000000,"") -> 16905 | L6: =IF(ISNUMBER(F6),F6+ROW()/10000000,"") -> 0.6100006
A7: =Raw_Data!A7 -> pTron Solero TB301 3A Type-C Data and Fast Charging Cable, Made in India, 480Mbps Data Sync, Strong and Durable 1.5-Meter Nylon Braided USB Cable for Type-C Devices for Charging Adapter (Black) | B7: =IFERROR(TRIM(LEFT(Raw_Data!A7,FIND(" ",Raw_Data!A7)-1)),Raw_Data!A7) -> pTron | C7: =IFERROR(LEFT(Raw_Data!B7,FIND("|",Raw_Data!B7)-1),Raw_Data!B7) -> Computers&Accessories | D7: =IFERROR(VALUE(SUBSTITUTE(SUBSTITUTE(TRIM(Raw_Data!C7),"₹",""),",","")),"") -> 149 | E7: =IFERROR(VALUE(SUBSTITUTE(SUBSTITUTE(TRIM(Raw_Data!D7),"₹",""),",","")),"") -> 1000 | F7: =IFERROR(VALUE(SUBSTITUTE(Raw_Data!E7,"%",""))/100,"") -> 0.85 | G7: =IFERROR(VALUE(Raw_Data!F7),"") -> 3.9 | H7: =IFERROR(VALUE(SUBSTITUTE(Raw_Data!G7,",","")),"") -> 24871 | I7: =IFERROR(E7-D7,"") -> 851 | J7: =IFERROR(D7*H7,"") -> 3705779 | K7: =IF(ISNUMBER(H7),H7+ROW()/10000000,"") -> 24871 | L7: =IF(ISNUMBER(F7),F7+ROW()/10000000,"") -> 0.8500007
A8: =Raw_Data!A8 -> boAt Micro USB 55 Tangle-free, Sturdy Micro USB Cable with 3A Fast Charging & 480mbps Data Transmission (Black) | B8: =IFERROR(TRIM(LEFT(Raw_Data!A8,FIND(" ",Raw_Data!A8)-1)),Raw_Data!A8) -> boAt | C8: =IFERROR(LEFT(Raw_Data!B8,FIND("|",Raw_Data!B8)-1),Raw_Data!B8) -> Computers&Accessories | D8: =IFERROR(VALUE(SUBSTITUTE(SUBSTITUTE(TRIM(Raw_Data!C8),"₹",""),",","")),"") -> 176.63 | E8: =IFERROR(VALUE(SUBSTITUTE(SUBSTITUTE(TRIM(Raw_Data!D8),"₹",""),",","")),"") -> 499 | F8: =IFERROR(VALUE(SUBSTITUTE(Raw_Data!E8,"%",""))/100,"") -> 0.65 | G8: =IFERROR(VALUE(Raw_Data!F8),"") -> 4.1 | H8: =IFERROR(VALUE(SUBSTITUTE(Raw_Data!G8,",","")),"") -> 15188 | I8: =IFERROR(E8-D8,"") -> 322.37 | J8: =IFERROR(D8*H8,"") -> 2682656.4 | K8: =IF(ISNUMBER(H8),H8+ROW()/10000000,"") -> 15188 | L8: =IF(ISNUMBER(F8),F8+ROW()/10000000,"") -> 0.6500008
A9: =Raw_Data!A9 -> MI Usb Type-C Cable Smartphone (Black) | B9: =IFERROR(TRIM(LEFT(Raw_Data!A9,FIND(" ",Raw_Data!A9)-1)),Raw_Data!A9) -> MI | C9: =IFERROR(LEFT(Raw_Data!B9,FIND("|",Raw_Data!B9)-1),Raw_Data!B9) -> Computers&Accessories | D9: =IFERROR(VALUE(SUBSTITUTE(SUBSTITUTE(TRIM(Raw_Data!C9),"₹",""),",","")),"") -> 229 | E9: =IFERROR(VALUE(SUBSTITUTE(SUBSTITUTE(TRIM(Raw_Data!D9),"₹",""),",","")),"") -> 299 | F9: =IFERROR(VALUE(SUBSTITUTE(Raw_Data!E9,"%",""))/100,"") -> 0.23 | G9: =IFERROR(VALUE(Raw_Data!F9),"") -> 4.3 | H9: =IFERROR(VALUE(SUBSTITUTE(Raw_Data!G9,",","")),"") -> 30411 | I9: =IFERROR(E9-D9,"") -> 70 | J9: =IFERROR(D9*H9,"") -> 6964119 | K9: =IF(ISNUMBER(H9),H9+ROW()/10000000,"") -> 30411 | L9: =IF(ISNUMBER(F9),F9+ROW()/10000000,"") -> 0.2300009
A10: =Raw_Data!A10 -> TP-Link USB WiFi Adapter for PC(TL-WN725N), N150 Wireless Network Adapter for Desktop - Nano Size WiFi Dongle Compatible with Windows 11/10/7/8/8.1/XP/ Mac OS 10.9-10.15 Linux Kernel 2.6.18-4.4.3 | B10: =IFERROR(TRIM(LEFT(Raw_Data!A10,FIND(" ",Raw_Data!A10)-1)),Raw_Data!A10) -> TP-Link | C10: =IFERROR(LEFT(Raw_Data!B10,FIND("|",Raw_Data!B10)-1),Raw_Data!B10) -> Computers&Accessories | D10: =IFERROR(VALUE(SUBSTITUTE(SUBSTITUTE(TRIM(Raw_Data!C10),"₹",""),",","")),"") -> 499 | E10: =IFERROR(VALUE(SUBSTITUTE(SUBSTITUTE(TRIM(Raw_Data!D10),"₹",""),",","")),"") -> 999 | F10: =IFERROR(VALUE(SUBSTITUTE(Raw_Data!E10,"%",""))/100,"") -> 0.5 | G10: =IFERROR(VALUE(Raw_Data!F10),"") -> 4.2 | H10: =IFERROR(VALUE(SUBSTITUTE(Raw_Data!G10,",","")),"") -> 179691 | I10: =IFERROR(E10-D10,"") -> 500 | J10: =IFERROR(D10*H10,"") -> 89665809 | K10: =IF(ISNUMBER(H10),H10+ROW()/10000000,"") -> 179691 | L10: =IF(ISNUMBER(F10),F10+ROW()/10000000,"") -> 0.500001
A11: =Raw_Data!A11 -> Ambrane Unbreakable 60W / 3A Fast Charging 1.5m Braided Micro USB Cable for Smartphones, Tablets, Laptops & Other Micro USB Devices, 480Mbps Data Sync, Quick Charge 3.0 (RCM15, Black) | B11: =IFERROR(TRIM(LEFT(Raw_Data!A11,FIND(" ",Raw_Data!A11)-1)),Raw_Data!A11) -> Ambrane | C11: =IFERROR(LEFT(Raw_Data!B11,FIND("|",Raw_Data!B11)-1),Raw_Data!B11) -> Computers&Accessories | D11: =IFERROR(VALUE(SUBSTITUTE(SUBSTITUTE(TRIM(Raw_Data!C11),"₹",""),",","")),"") -> 199 | E11: =IFERROR(VALUE(SUBSTITUTE(SUBSTITUTE(TRIM(Raw_Data!D11),"₹",""),",","")),"") -> 299 | F11: =IFERROR(VALUE(SUBSTITUTE(Raw_Data!E11,"%",""))/100,"") -> 0.33 | G11: =IFERROR(VALUE(Raw_Data!F11),"") -> 4 | H11: =IFERROR(VALUE(SUBSTITUTE(Raw_Data!G11,",","")),"") -> 43994 | I11: =IFERROR(E11-D11,"") -> 100 | J11: =IFERROR(D11*H11,"") -> 8754806 | K11: =IF(ISNUMBER(H11),H11+ROW()/10000000,"") -> 43994 | L11: =IF(ISNUMBER(F11),F11+ROW()/10000000,"") -> 0.3300011
A12: =Raw_Data!A12 -> Portronics Konnect L POR-1081 Fast Charging 3A Type-C Cable 1.2Meter with Charge & Sync Function for All Type-C Devices (Grey) | B12: =IFERROR(TRIM(LEFT(Raw_Data!A12,FIND(" ",Raw_Data!A12)-1)),Raw_Data!A12) -> Portronics | C12: =IFERROR(LEFT(Raw_Data!B12,FIND("|",Raw_Data!B12)-1),Raw_Data!B12) -> Computers&Accessories | D12: =IFERROR(VALUE(SUBSTITUTE(SUBSTITUTE(TRIM(Raw_Data!C12),"₹",""),",","")),"") -> 154 | E12: =IFERROR(VALUE(SUBSTITUTE(SUBSTITUTE(TRIM(Raw_Data!D12),"₹",""),",","")),"") -> 339 | F12: =IFERROR(VALUE(SUBSTITUTE(Raw_Data!E12,"%",""))/100,"") -> 0.55 | G12: =IFERROR(VALUE(Raw_Data!F12),"") -> 4.3 | H12: =IFERROR(VALUE(SUBSTITUTE(Raw_Data!G12,",","")),"") -> 13391 | I12: =IFERROR(E12-D12,"") -> 185 | J12: =IFERROR(D12*H12,"") -> 2062214 | K12: =IF(ISNUMBER(H12),H12+ROW()/10000000,"") -> 13391 | L12: =IF(ISNUMBER(F12),F12+ROW()/10000000,"") -> 0.5500012
A13: =Raw_Data!A13 -> boAt Rugged v3 Extra Tough Unbreakable Braided Micro USB Cable 1.5 Meter (Black) | B13: =IFERROR(TRIM(LEFT(Raw_Data!A13,FIND(" ",Raw_Data!A13)-1)),Raw_Data!A13) -> boAt | C13: =IFERROR(LEFT(Raw_Data!B13,FIND("|",Raw_Data!B13)-1),Raw_Data!B13) -> Computers&Accessories | D13: =IFERROR(VALUE(SUBSTITUTE(SUBSTITUTE(TRIM(Raw_Data!C13),"₹",""),",","")),"") -> 299 | E13: =IFERROR(VALUE(SUBSTITUTE(SUBSTITUTE(TRIM(Raw_Data!D13),"₹",""),",","")),"") -> 799 | F13: =IFERROR(VALUE(SUBSTITUTE(Raw_Data!E13,"%",""))/100,"") -> 0.63 | G13: =IFERROR(VALUE(Raw_Data!F13),"") -> 4.2 | H13: =IFERROR(VALUE(SUBSTITUTE(Raw_Data!G13,",","")),"") -> 94363 | I13: =IFERROR(E13-D13,"") -> 500 | J13: =IFERROR(D13*H13,"") -> 28214537 | K13: =IF(ISNUMBER(H13),H13+ROW()/10000000,"") -> 94363 | L13: =IF(ISNUMBER(F13),F13+ROW()/10000000,"") -> 0.6300013
... A1466: =Raw_Data!A1466 -> Borosil Jumbo 1000-Watt Grill Sandwich Maker (Black) | B1466: =IFERROR(TRIM(LEFT(Raw_Data!A1466,FIND(" ",Raw_Data!A1466)-1)),Raw_Data!A1466) -> Borosil | C1466: =IFERROR(LEFT(Raw_Data!B1466,FIND("|",Raw_Data!B1466)-1),Raw_Data!B1466) -> Home&Kitchen | D1466: =IFERROR(VALUE(SUBSTITUTE(SUBSTITUTE(TRIM(Raw_Data!C1466),"₹",""),",","")),"") -> 2863 | E1466: =IFERROR(VALUE(SUBSTITUTE(SUBSTITUTE(TRIM(Raw_Data!D1466),"₹",""),",","")),"") -> 3690 | F1466: =IFERROR(VALUE(SUBSTITUTE(Raw_Data!E1466,"%",""))/100,"") -> 0.22 | G1466: =IFERROR(VALUE(Raw_Data!F1466),"") -> 4.3 | H1466: =IFERROR(VALUE(SUBSTITUTE(Raw_Data!G1466,",","")),"") -> 6987 | I1466: =IFERROR(E1466-D1466,"") -> 827 | J1466: =IFERROR(D1466*H1466,"") -> 20003781 | K1466: =IF(ISNUMBER(H1466),H1466+ROW()/10000000,"") -> 6987.0001 | L1466: =IF(ISNUMBER(F1466),F1466+ROW()/10000000,"") -> 0.2201466

Sheet Brand_Summary
A1: Brand | B1: Product Count | C1: Avg Discounted Price | D1: Avg Actual Price | E1: Avg Discount % | F1: Avg Rating | G1: Total Reviews
A2: boAt | B2: =COUNTIF(Clean_Data!$B$2:$B$1466,A2) -> 68 | C2: =AVERAGEIF(Clean_Data!$B$2:$B$1466,A2,Clean_Data!$D$2:$D$1466) -> 1044.4556 | D2: =AVERAGEIF(Clean_Data!$B$2:$B$1466,A2,Clean_Data!$E$2:$E$1466) -> 3268.4853 | E2: =AVERAGEIF(Clean_Data!$B$2:$B$1466,A2,Clean_Data!$F$2:$F$1466) -> 0.63044118 | F2: =AVERAGEIF(Clean_Data!$B$2:$B$1466,A2,Clean_Data!$G$2:$G$1466) -> 4.0852941 | G2: =SUMIF(Clean_Data!$B$2:$B$1466,A2,Clean_Data!$H$2:$H$1466) -> 4445359
A3: Redmi | B3: =COUNTIF(Clean_Data!$B$2:$B$1466,A3) -> 26 | C3: =AVERAGEIF(Clean_Data!$B$2:$B$1466,A3,Clean_Data!$D$2:$D$1466) -> 13787.462 | D3: =AVERAGEIF(Clean_Data!$B$2:$B$1466,A3,Clean_Data!$E$2:$E$1466) -> 18806.692 | E3: =AVERAGEIF(Clean_Data!$B$2:$B$1466,A3,Clean_Data!$F$2:$F$1466) -> 0.25692308 | F3: =AVERAGEIF(Clean_Data!$B$2:$B$1466,A3,Clean_Data!$G$2:$G$1466) -> 4.0538462 | G3: =SUMIF(Clean_Data!$B$2:$B$1466,A3,Clean_Data!$H$2:$H$1466) -> 1878482
A4: AmazonBasics | B4: =COUNTIF(Clean_Data!$B$2:$B$1466,A4) -> 38 | C4: =AVERAGEIF(Clean_Data!$B$2:$B$1466,A4,Clean_Data!$D$2:$D$1466) -> 1317.7853 | D4: =AVERAGEIF(Clean_Data!$B$2:$B$1466,A4,Clean_Data!$E$2:$E$1466) -> 2737.0263 | E4: =AVERAGEIF(Clean_Data!$B$2:$B$1466,A4,Clean_Data!$F$2:$F$1466) -> 0.56736842 | F4: =AVERAGEIF(Clean_Data!$B$2:$B$1466,A4,Clean_Data!$G$2:$G$1466) -> 4.3078947 | G4: =SUMIF(Clean_Data!$B$2:$B$1466,A4,Clean_Data!$H$2:$H$1466) -> 2034664
A5: SanDisk | B5: =COUNTIF(Clean_Data!$B$2:$B$1466,A5) -> 17 | C5: =AVERAGEIF(Clean_Data!$B$2:$B$1466,A5,Clean_Data!$D$2:$D$1466) -> 1389.5882 | D5: =AVERAGEIF(Clean_Data!$B$2:$B$1466,A5,Clean_Data!$E$2:$E$1466) -> 3602.9412 | E5: =AVERAGEIF(Clean_Data!$B$2:$B$1466,A5,Clean_Data!$F$2:$F$1466) -> 0.54352941 | F5: =AVERAGEIF(Clean_Data!$B$2:$B$1466,A5,Clean_Data!$G$2:$G$1466) -> 4.3705882 | G5: =SUMIF(Clean_Data!$B$2:$B$1466,A5,Clean_Data!$H$2:$H$1466) -> 1426074
A6: Amazon | B6: =COUNTIF(Clean_Data!$B$2:$B$1466,A6) -> 25 | C6: =AVERAGEIF(Clean_Data!$B$2:$B$1466,A6,Clean_Data!$D$2:$D$1466) -> 514.6 | D6: =AVERAGEIF(Clean_Data!$B$2:$B$1466,A6,Clean_Data!$E$2:$E$1466) -> 1282.08 | E6: =AVERAGEIF(Clean_Data!$B$2:$B$1466,A6,Clean_Data!$F$2:$F$1466) -> 0.584 | F6: =AVERAGEIF(Clean_Data!$B$2:$B$1466,A6,Clean_Data!$G$2:$G$1466) -> 4.14 | G6: =SUMIF(Clean_Data!$B$2:$B$1466,A6,Clean_Data!$H$2:$H$1466) -> 1207959
A7: TP-Link | B7: =COUNTIF(Clean_Data!$B$2:$B$1466,A7) -> 20 | C7: =AVERAGEIF(Clean_Data!$B$2:$B$1466,A7,Clean_Data!$D$2:$D$1466) -> 1371 | D7: =AVERAGEIF(Clean_Data!$B$2:$B$1466,A7,Clean_Data!$E$2:$E$1466) -> 2481 | E7: =AVERAGEIF(Clean_Data!$B$2:$B$1466,A7,Clean_Data!$F$2:$F$1466) -> 0.4295 | F7: =AVERAGEIF(Clean_Data!$B$2:$B$1466,A7,Clean_Data!$G$2:$G$1466) -> 4.31 | G7: =SUMIF(Clean_Data!$B$2:$B$1466,A7,Clean_Data!$H$2:$H$1466) -> 1354798
A8: Samsung | B8: =COUNTIF(Clean_Data!$B$2:$B$1466,A8) -> 36 | C8: =AVERAGEIF(Clean_Data!$B$2:$B$1466,A8,Clean_Data!$D$2:$D$1466) -> 13779.139 | D8: =AVERAGEIF(Clean_Data!$B$2:$B$1466,A8,Clean_Data!$E$2:$E$1466) -> 21343.694 | E8: =AVERAGEIF(Clean_Data!$B$2:$B$1466,A8,Clean_Data!$F$2:$F$1466) -> 0.32361111 | F8: =AVERAGEIF(Clean_Data!$B$2:$B$1466,A8,Clean_Data!$G$2:$G$1466) -> 4.2027778 | G8: =SUMIF(Clean_Data!$B$2:$B$1466,A8,Clean_Data!$H$2:$H$1466) -> 901882
A9: JBL | B9: =COUNTIF(Clean_Data!$B$2:$B$1466,A9) -> 8 | C9: =AVERAGEIF(Clean_Data!$B$2:$B$1466,A9,Clean_Data!$D$2:$D$1466) -> 942.75 | D9: =AVERAGEIF(Clean_Data!$B$2:$B$1466,A9,Clean_Data!$E$2:$E$1466) -> 1724.125 | E9: =AVERAGEIF(Clean_Data!$B$2:$B$1466,A9,Clean_Data!$F$2:$F$1466) -> 0.45875 | F9: =AVERAGEIF(Clean_Data!$B$2:$B$1466,A9,Clean_Data!$G$2:$G$1466) -> 4.025 | G9: =SUMIF(Clean_Data!$B$2:$B$1466,A9,Clean_Data!$H$2:$H$1466) -> 891075
A10: MI | B10: =COUNTIF(Clean_Data!$B$2:$B$1466,A10) -> 28 | C10: =AVERAGEIF(Clean_Data!$B$2:$B$1466,A10,Clean_Data!$D$2:$D$1466) -> 9492.1071 | D10: =AVERAGEIF(Clean_Data!$B$2:$B$1466,A10,Clean_Data!$E$2:$E$1466) -> 14013.286 | E10: =AVERAGEIF(Clean_Data!$B$2:$B$1466,A10,Clean_Data!$F$2:$F$1466) -> 0.29892857 | F10: =AVERAGEIF(Clean_Data!$B$2:$B$1466,A10,Clean_Data!$G$2:$G$1466) -> 4.2642857 | G10: =SUMIF(Clean_Data!$B$2:$B$1466,A10,Clean_Data!$H$2:$H$1466) -> 1069730
A11: Noise | B11: =COUNTIF(Clean_Data!$B$2:$B$1466,A11) -> 24 | C11: =AVERAGEIF(Clean_Data!$B$2:$B$1466,A11,Clean_Data!$D$2:$D$1466) -> 2248.875 | D11: =AVERAGEIF(Clean_Data!$B$2:$B$1466,A11,Clean_Data!$E$2:$E$1466) -> 5165.2917 | E11: =AVERAGEIF(Clean_Data!$B$2:$B$1466,A11,Clean_Data!$F$2:$F$1466) -> 0.57125 | F11: =AVERAGEIF(Clean_Data!$B$2:$B$1466,A11,Clean_Data!$G$2:$G$1466) -> 3.9791667 | G11: =SUMIF(Clean_Data!$B$2:$B$1466,A11,Clean_Data!$H$2:$H$1466) -> 621421
A12: Total / Overall | B12: =SUM(B2:B11) -> 290 | G12: =SUM(G2:G11) -> 15831444

Sheet Category_Summary
A1: Category | B1: Product Count | C1: Avg Discounted Price | D1: Avg Actual Price | E1: Avg Rating | F1: Total Reviews
A2: Electronics | B2: =COUNTIF(Clean_Data!$C$2:$C$1466,A2) -> 526 | C2: =IFERROR(AVERAGEIF(Clean_Data!$C$2:$C$1466,A2,Clean_Data!$D$2:$D$1466),0) -> 5965.8878 | D2: =IFERROR(AVERAGEIF(Clean_Data!$C$2:$C$1466,A2,Clean_Data!$E$2:$E$1466),0) -> 10127.312 | E2: =IFERROR(AVERAGEIF(Clean_Data!$C$2:$C$1466,A2,Clean_Data!$G$2:$G$1466),0) -> 4.081749 | F2: =SUMIF(Clean_Data!$C$2:$C$1466,A2,Clean_Data!$H$2:$H$1466) -> 15778848
A3: Computers&Accessories | B3: =COUNTIF(Clean_Data!$C$2:$C$1466,A3) -> 453 | C3: =IFERROR(AVERAGEIF(Clean_Data!$C$2:$C$1466,A3,Clean_Data!$D$2:$D$1466),0) -> 842.65038 | D3: =IFERROR(AVERAGEIF(Clean_Data!$C$2:$C$1466,A3,Clean_Data!$E$2:$E$1466),0) -> 1683.6231 | E3: =IFERROR(AVERAGEIF(Clean_Data!$C$2:$C$1466,A3,Clean_Data!$G$2:$G$1466),0) -> 4.1549669 | F3: =SUMIF(Clean_Data!$C$2:$C$1466,A3,Clean_Data!$H$2:$H$1466) -> 7728689
A4: Home&Kitchen | B4: =COUNTIF(Clean_Data!$C$2:$C$1466,A4) -> 448 | C4: =IFERROR(AVERAGEIF(Clean_Data!$C$2:$C$1466,A4,Clean_Data!$D$2:$D$1466),0) -> 2330.6156 | D4: =IFERROR(AVERAGEIF(Clean_Data!$C$2:$C$1466,A4,Clean_Data!$E$2:$E$1466),0) -> 4162.0737 | E4: =IFERROR(AVERAGEIF(Clean_Data!$C$2:$C$1466,A4,Clean_Data!$G$2:$G$1466),0) -> 4.0407159 | F4: =SUMIF(Clean_Data!$C$2:$C$1466,A4,Clean_Data!$H$2:$H$1466) -> 2991069
A5: OfficeProducts | B5: =COUNTIF(Clean_Data!$C$2:$C$1466,A5) -> 31 | C5: =IFERROR(AVERAGEIF(Clean_Data!$C$2:$C$1466,A5,Clean_Data!$D$2:$D$1466),0) -> 301.58065 | D5: =IFERROR(AVERAGEIF(Clean_Data!$C$2:$C$1466,A5,Clean_Data!$E$2:$E$1466),0) -> 397.19355 | E5: =IFERROR(AVERAGEIF(Clean_Data!$C$2:$C$1466,A5,Clean_Data!$G$2:$G$1466),0) -> 4.3096774 | F5: =SUMIF(Clean_Data!$C$2:$C$1466,A5,Clean_Data!$H$2:$H$1466) -> 149675
A6: MusicalInstruments | B6: =COUNTIF(Clean_Data!$C$2:$C$1466,A6) -> 2 | C6: =IFERROR(AVERAGEIF(Clean_Data!$C$2:$C$1466,A6,Clean_Data!$D$2:$D$1466),0) -> 638 | D6: =IFERROR(AVERAGEIF(Clean_Data!$C$2:$C$1466,A6,Clean_Data!$E$2:$E$1466),0) -> 1347 | E6: =IFERROR(AVERAGEIF(Clean_Data!$C$2:$C$1466,A6,Clean_Data!$G$2:$G$1466),0) -> 3.9 | F6: =SUMIF(Clean_Data!$C$2:$C$1466,A6,Clean_Data!$H$2:$H$1466) -> 88882
A7: HomeImprovement | B7: =COUNTIF(Clean_Data!$C$2:$C$1466,A7) -> 2 | C7: =IFERROR(AVERAGEIF(Clean_Data!$C$2:$C$1466,A7,Clean_Data!$D$2:$D$1466),0) -> 337 | D7: =IFERROR(AVERAGEIF(Clean_Data!$C$2:$C$1466,A7,Clean_Data!$E$2:$E$1466),0) -> 799 | E7: =IFERROR(AVERAGEIF(Clean_Data!$C$2:$C$1466,A7,Clean_Data!$G$2:$G$1466),0) -> 4.25 | F7: =SUMIF(Clean_Data!$C$2:$C$1466,A7,Clean_Data!$H$2:$H$1466) -> 8566
A8: Toys&Games | B8: =COUNTIF(Clean_Data!$C$2:$C$1466,A8) -> 1 | C8: =IFERROR(AVERAGEIF(Clean_Data!$C$2:$C$1466,A8,Clean_Data!$D$2:$D$1466),0) -> 150 | D8: =IFERROR(AVERAGEIF(Clean_Data!$C$2:$C$1466,A8,Clean_Data!$E$2:$E$1466),0) -> 150 | E8: =IFERROR(AVERAGEIF(Clean_Data!$C$2:$C$1466,A8,Clean_Data!$G$2:$G$1466),0) -> 4.3 | F8: =SUMIF(Clean_Data!$C$2:$C$1466,A8,Clean_Data!$H$2:$H$1466) -> 15867
A9: Car&Motorbike | B9: =COUNTIF(Clean_Data!$C$2:$C$1466,A9) -> 1 | C9: =IFERROR(AVERAGEIF(Clean_Data!$C$2:$C$1466,A9,Clean_Data!$D$2:$D$1466),0) -> 2339 | D9: =IFERROR(AVERAGEIF(Clean_Data!$C$2:$C$1466,A9,Clean_Data!$E$2:$E$1466),0) -> 4000 | E9: =IFERROR(AVERAGEIF(Clean_Data!$C$2:$C$1466,A9,Clean_Data!$G$2:$G$1466),0) -> 3.8 | F9: =SUMIF(Clean_Data!$C$2:$C$1466,A9,Clean_Data!$H$2:$H$1466) -> 1118
A10: Health&PersonalCare | B10: =COUNTIF(Clean_Data!$C$2:$C$1466,A10) -> 1 | C10: =IFERROR(AVERAGEIF(Clean_Data!$C$2:$C$1466,A10,Clean_Data!$D$2:$D$1466),0) -> 899 | D10: =IFERROR(AVERAGEIF(Clean_Data!$C$2:$C$1466,A10,Clean_Data!$E$2:$E$1466),0) -> 1900 | E10: =IFERROR(AVERAGEIF(Clean_Data!$C$2:$C$1466,A10,Clean_Data!$G$2:$G$1466),0) -> 4 | F10: =SUMIF(Clean_Data!$C$2:$C$1466,A10,Clean_Data!$H$2:$H$1466) -> 3663

Sheet Top_Products
A1: Top 15 Products by Review Volume
A2: Rank | B2: Product Name | C2: Brand | D2: Rating | E2: Rating Count | F2: Discounted Price | G2: Chart Label
A3: 1 | B3: =INDEX(Clean_Data!$A$2:$A$1466,MATCH(LARGE(Clean_Data!$K$2:$K$1466,1),Clean_Data!$K$2:$K$1466,0)) -> Amazon Basics High-Speed HDMI Cable, 6 Feet (2-Pack),Black | C3: =INDEX(Clean_Data!$B$2:$B$1466,MATCH(LARGE(Clean_Data!$K$2:$K$1466,1),Clean_Data!$K$2:$K$1466,0)) -> Amazon | D3: =INDEX(Clean_Data!$G$2:$G$1466,MATCH(LARGE(Clean_Data!$K$2:$K$1466,1),Clean_Data!$K$2:$K$1466,0)) -> 4.4 | E3: =INDEX(Clean_Data!$H$2:$H$1466,MATCH(LARGE(Clean_Data!$K$2:$K$1466,1),Clean_Data!$K$2:$K$1466,0)) -> 426973 | F3: =INDEX(Clean_Data!$D$2:$D$1466,MATCH(LARGE(Clean_Data!$K$2:$K$1466,1),Clean_Data!$K$2:$K$1466,0)) -> 309 | G3: =LEFT(B3,22)&"…" -> Amazon Basics High-Spe…
A4: 2 | B4: =INDEX(Clean_Data!$A$2:$A$1466,MATCH(LARGE(Clean_Data!$K$2:$K$1466,2),Clean_Data!$K$2:$K$1466,0)) -> Amazon Basics High-Speed HDMI Cable, 6 Feet - Supports Ethernet, 3D, 4K video,Black | C4: =INDEX(Clean_Data!$B$2:$B$1466,MATCH(LARGE(Clean_Data!$K$2:$K$1466,2),Clean_Data!$K$2:$K$1466,0)) -> Amazon | D4: =INDEX(Clean_Data!$G$2:$G$1466,MATCH(LARGE(Clean_Data!$K$2:$K$1466,2),Clean_Data!$K$2:$K$1466,0)) -> 4.4 | E4: =INDEX(Clean_Data!$H$2:$H$1466,MATCH(LARGE(Clean_Data!$K$2:$K$1466,2),Clean_Data!$K$2:$K$1466,0)) -> 426973 | F4: =INDEX(Clean_Data!$D$2:$D$1466,MATCH(LARGE(Clean_Data!$K$2:$K$1466,2),Clean_Data!$K$2:$K$1466,0)) -> 309 | G4: =LEFT(B4,22)&"…" -> Amazon Basics High-Spe…
A5: 3 | B5: =INDEX(Clean_Data!$A$2:$A$1466,MATCH(LARGE(Clean_Data!$K$2:$K$1466,3),Clean_Data!$K$2:$K$1466,0)) -> AmazonBasics Flexible Premium HDMI Cable (Black, 4K@60Hz, 18Gbps), 3-Foot | C5: =INDEX(Clean_Data!$B$2:$B$1466,MATCH(LARGE(Clean_Data!$K$2:$K$1466,3),Clean_Data!$K$2:$K$1466,0)) -> AmazonBasics | D5: =INDEX(Clean_Data!$G$2:$G$1466,MATCH(LARGE(Clean_Data!$K$2:$K$1466,3),Clean_Data!$K$2:$K$1466,0)) -> 4.4 | E5: =INDEX(Clean_Data!$H$2:$H$1466,MATCH(LARGE(Clean_Data!$K$2:$K$1466,3),Clean_Data!$K$2:$K$1466,0)) -> 426973 | F5: =INDEX(Clean_Data!$D$2:$D$1466,MATCH(LARGE(Clean_Data!$K$2:$K$1466,3),Clean_Data!$K$2:$K$1466,0)) -> 219 | G5: =LEFT(B5,22)&"…" -> AmazonBasics Flexible …
A6: 4 | B6: =INDEX(Clean_Data!$A$2:$A$1466,MATCH(LARGE(Clean_Data!$K$2:$K$1466,4),Clean_Data!$K$2:$K$1466,0)) -> AmazonBasics Flexible Premium HDMI Cable (Black, 4K@60Hz, 18Gbps), 3-Foot | C6: =INDEX(Clean_Data!$B$2:$B$1466,MATCH(LARGE(Clean_Data!$K$2:$K$1466,4),Clean_Data!$K$2:$K$1466,0)) -> AmazonBasics | D6: =INDEX(Clean_Data!$G$2:$G$1466,MATCH(LARGE(Clean_Data!$K$2:$K$1466,4),Clean_Data!$K$2:$K$1466,0)) -> 4.4 | E6: =INDEX(Clean_Data!$H$2:$H$1466,MATCH(LARGE(Clean_Data!$K$2:$K$1466,4),Clean_Data!$K$2:$K$1466,0)) -> 426972 | F6: =INDEX(Clean_Data!$D$2:$D$1466,MATCH(LARGE(Clean_Data!$K$2:$K$1466,4),Clean_Data!$K$2:$K$1466,0)) -> 219 | G6: =LEFT(B6,22)&"…" -> AmazonBasics Flexible …
A7: 5 | B7: =INDEX(Clean_Data!$A$2:$A$1466,MATCH(LARGE(Clean_Data!$K$2:$K$1466,5),Clean_Data!$K$2:$K$1466,0)) -> boAt Bassheads 100 in Ear Wired Earphones with Mic(Furious Red) | C7: =INDEX(Clean_Data!$B$2:$B$1466,MATCH(LARGE(Clean_Data!$K$2:$K$1466,5),Clean_Data!$K$2:$K$1466,0)) -> boAt | D7: =INDEX(Clean_Data!$G$2:$G$1466,MATCH(LARGE(Clean_Data!$K$2:$K$1466,5),Clean_Data!$K$2:$K$1466,0)) -> 4.1 | E7: =INDEX(Clean_Data!$H$2:$H$1466,MATCH(LARGE(Clean_Data!$K$2:$K$1466,5),Clean_Data!$K$2:$K$1466,0)) -> 363713 | F7: =INDEX(Clean_Data!$D$2:$D$1466,MATCH(LARGE(Clean_Data!$K$2:$K$1466,5),Clean_Data!$K$2:$K$1466,0)) -> 379 | G7: =LEFT(B7,22)&"…" -> boAt Bassheads 100 in …
A8: 6 | B8: =INDEX(Clean_Data!$A$2:$A$1466,MATCH(LARGE(Clean_Data!$K$2:$K$1466,6),Clean_Data!$K$2:$K$1466,0)) -> boAt Bassheads 100 in Ear Wired Earphones with Mic(Taffy Pink) | C8: =INDEX(Clean_Data!$B$2:$B$1466,MATCH(LARGE(Clean_Data!$K$2:$K$1466,6),Clean_Data!$K$2:$K$1466,0)) -> boAt | D8: =INDEX(Clean_Data!$G$2:$G$1466,MATCH(LARGE(Clean_Data!$K$2:$K$1466,6),Clean_Data!$K$2:$K$1466,0)) -> 4.1 | E8: =INDEX(Clean_Data!$H$2:$H$1466,MATCH(LARGE(Clean_Data!$K$2:$K$1466,6),Clean_Data!$K$2:$K$1466,0)) -> 363713 | F8: =INDEX(Clean_Data!$D$2:$D$1466,MATCH(LARGE(Clean_Data!$K$2:$K$1466,6),Clean_Data!$K$2:$K$1466,0)) -> 349 | G8: =LEFT(B8,22)&"…" -> boAt Bassheads 100 in …
A9: 7 | B9: =INDEX(Clean_Data!$A$2:$A$1466,MATCH(LARGE(Clean_Data!$K$2:$K$1466,7),Clean_Data!$K$2:$K$1466,0)) -> boAt BassHeads 100 in-Ear Wired Headphones with Mic (Black) | C9: =INDEX(Clean_Data!$B$2:$B$1466,MATCH(LARGE(Clean_Data!$K$2:$K$1466,7),Clean_Data!$K$2:$K$1466,0)) -> boAt | D9: =INDEX(Clean_Data!$G$2:$G$1466,MATCH(LARGE(Clean_Data!$K$2:$K$1466,7),Clean_Data!$K$2:$K$1466,0)) -> 4.1 | E9: =INDEX(Clean_Data!$H$2:$H$1466,MATCH(LARGE(Clean_Data!$K$2:$K$1466,7),Clean_Data!$K$2:$K$1466,0)) -> 363711 | F9: =INDEX(Clean_Data!$D$2:$D$1466,MATCH(LARGE(Clean_Data!$K$2:$K$1466,7),Clean_Data!$K$2:$K$1466,0)) -> 365 | G9: =LEFT(B9,22)&"…" -> boAt BassHeads 100 in-…
A10: 8 | B10: =INDEX(Clean_Data!$A$2:$A$1466,MATCH(LARGE(Clean_Data!$K$2:$K$1466,8),Clean_Data!$K$2:$K$1466,0)) -> Redmi 9A Sport (Coral Green, 2GB RAM, 32GB Storage) | 2GHz Octa-core Helio G25 Processor | 5000 mAh Battery | C10: =INDEX(Clean_Data!$B$2:$B$1466,MATCH(LARGE(Clean_Data!$K$2:$K$1466,8),Clean_Data!$K$2:$K$1466,0)) -> Redmi | D10: =INDEX(Clean_Data!$G$2:$G$1466,MATCH(LARGE(Clean_Data!$K$2:$K$1466,8),Clean_Data!$K$2:$K$1466,0)) -> 4.1 | E10: =INDEX(Clean_Data!$H$2:$H$1466,MATCH(LARGE(Clean_Data!$K$2:$K$1466,8),Clean_Data!$K$2:$K$1466,0)) -> 313836 | F10: =INDEX(Clean_Data!$D$2:$D$1466,MATCH(LARGE(Clean_Data!$K$2:$K$1466,8),Clean_Data!$K$2:$K$1466,0)) -> 6499 | G10: =LEFT(B10,22)&"…" -> Redmi 9A Sport (Coral …
A11: 9 | B11: =INDEX(Clean_Data!$A$2:$A$1466,MATCH(LARGE(Clean_Data!$K$2:$K$1466,9),Clean_Data!$K$2:$K$1466,0)) -> Redmi 9 Activ (Carbon Black, 4GB RAM, 64GB Storage) | Octa-core Helio G35 | 5000 mAh Battery | C11: =INDEX(Clean_Data!$B$2:$B$1466,MATCH(LARGE(Clean_Data!$K$2:$K$1466,9),Clean_Data!$K$2:$K$1466,0)) -> Redmi | D11: =INDEX(Clean_Data!$G$2:$G$1466,MATCH(LARGE(Clean_Data!$K$2:$K$1466,9),Clean_Data!$K$2:$K$1466,0)) -> 4.1 | E11: =INDEX(Clean_Data!$H$2:$H$1466,MATCH(LARGE(Clean_Data!$K$2:$K$1466,9),Clean_Data!$K$2:$K$1466,0)) -> 313836 | F11: =INDEX(Clean_Data!$D$2:$D$1466,MATCH(LARGE(Clean_Data!$K$2:$K$1466,9),Clean_Data!$K$2:$K$1466,0)) -> 8499 | G11: =LEFT(B11,22)&"…" -> Redmi 9 Activ (Carbon …
A12: 10 | B12: =INDEX(Clean_Data!$A$2:$A$1466,MATCH(LARGE(Clean_Data!$K$2:$K$1466,10),Clean_Data!$K$2:$K$1466,0)) -> Redmi 9A Sport (Coral Green, 3GB RAM, 32GB Storage) | 2GHz Octa-core Helio G25 Processor | 5000 mAh Battery | C12: =INDEX(Clean_Data!$B$2:$B$1466,MATCH(LARGE(Clean_Data!$K$2:$K$1466,10),Clean_Data!$K$2:$K$1466,0)) -> Redmi | D12: =INDEX(Clean_Data!$G$2:$G$1466,MATCH(LARGE(Clean_Data!$K$2:$K$1466,10),Clean_Data!$K$2:$K$1466,0)) -> 4.1 | E12: =INDEX(Clean_Data!$H$2:$H$1466,MATCH(LARGE(Clean_Data!$K$2:$K$1466,10),Clean_Data!$K$2:$K$1466,0)) -> 313832 | F12: =INDEX(Clean_Data!$D$2:$D$1466,MATCH(LARGE(Clean_Data!$K$2:$K$1466,10),Clean_Data!$K$2:$K$1466,0)) -> 7499 | G12: =LEFT(B12,22)&"…" -> Redmi 9A Sport (Coral …
A13: 11 | B13: =INDEX(Clean_Data!$A$2:$A$1466,MATCH(LARGE(Clean_Data!$K$2:$K$1466,11),Clean_Data!$K$2:$K$1466,0)) -> Redmi 9A Sport (Carbon Black, 2GB RAM, 32GB Storage) | 2GHz Octa-core Helio G25 Processor | 5000 mAh Battery | C13: =INDEX(Clean_Data!$B$2:$B$1466,MATCH(LARGE(Clean_Data!$K$2:$K$1466,11),Clean_Data!$K$2:$K$1466,0)) -> Redmi | D13: =INDEX(Clean_Data!$G$2:$G$1466,MATCH(LARGE(Clean_Data!$K$2:$K$1466,11),Clean_Data!$K$2:$K$1466,0)) -> 4.1 | E13: =INDEX(Clean_Data!$H$2:$H$1466,MATCH(LARGE(Clean_Data!$K$2:$K$1466,11),Clean_Data!$K$2:$K$1466,0)) -> 313832 | F13: =INDEX(Clean_Data!$D$2:$D$1466,MATCH(LARGE(Clean_Data!$K$2:$K$1466,11),Clean_Data!$K$2:$K$1466,0)) -> 6499 | G13: =LEFT(B13,22)&"…" -> Redmi 9A Sport (Carbon…
A14: 12 | B14: =INDEX(Clean_Data!$A$2:$A$1466,MATCH(LARGE(Clean_Data!$K$2:$K$1466,12),Clean_Data!$K$2:$K$1466,0)) -> boAt Bassheads 225 in Ear Wired Earphones with Mic(Blue) | C14: =INDEX(Clean_Data!$B$2:$B$1466,MATCH(LARGE(Clean_Data!$K$2:$K$1466,12),Clean_Data!$K$2:$K$1466,0)) -> boAt | D14: =INDEX(Clean_Data!$G$2:$G$1466,MATCH(LARGE(Clean_Data!$K$2:$K$1466,12),Clean_Data!$K$2:$K$1466,0)) -> 4.1 | E14: =INDEX(Clean_Data!$H$2:$H$1466,MATCH(LARGE(Clean_Data!$K$2:$K$1466,12),Clean_Data!$K$2:$K$1466,0)) -> 273189 | F14: =INDEX(Clean_Data!$D$2:$D$1466,MATCH(LARGE(Clean_Data!$K$2:$K$1466,12),Clean_Data!$K$2:$K$1466,0)) -> 699 | G14: =LEFT(B14,22)&"…" -> boAt Bassheads 225 in …
A15: 13 | B15: =INDEX(Clean_Data!$A$2:$A$1466,MATCH(LARGE(Clean_Data!$K$2:$K$1466,13),Clean_Data!$K$2:$K$1466,0)) -> Pigeon Polypropylene Mini Handy and Compact Chopper with 3 Blades for Effortlessly Chopping Vegetables and Fruits for Your Kitchen (12420, Green, 400 ml) | C15: =INDEX(Clean_Data!$B$2:$B$1466,MATCH(LARGE(Clean_Data!$K$2:$K$1466,13),Clean_Data!$K$2:$K$1466,0)) -> Pigeon | D15: =INDEX(Clean_Data!$G$2:$G$1466,MATCH(LARGE(Clean_Data!$K$2:$K$1466,13),Clean_Data!$K$2:$K$1466,0)) -> 4.1 | E15: =INDEX(Clean_Data!$H$2:$H$1466,MATCH(LARGE(Clean_Data!$K$2:$K$1466,13),Clean_Data!$K$2:$K$1466,0)) -> 270563 | F15: =INDEX(Clean_Data!$D$2:$D$1466,MATCH(LARGE(Clean_Data!$K$2:$K$1466,13),Clean_Data!$K$2:$K$1466,0)) -> 199 | G15: =LEFT(B15,22)&"…" -> Pigeon Polypropylene M…
A16: 14 | B16: =INDEX(Clean_Data!$A$2:$A$1466,MATCH(LARGE(Clean_Data!$K$2:$K$1466,14),Clean_Data!$K$2:$K$1466,0)) -> SanDisk Cruzer Blade 32GB USB Flash Drive | C16: =INDEX(Clean_Data!$B$2:$B$1466,MATCH(LARGE(Clean_Data!$K$2:$K$1466,14),Clean_Data!$K$2:$K$1466,0)) -> SanDisk | D16: =INDEX(Clean_Data!$G$2:$G$1466,MATCH(LARGE(Clean_Data!$K$2:$K$1466,14),Clean_Data!$K$2:$K$1466,0)) -> 4.3 | E16: =INDEX(Clean_Data!$H$2:$H$1466,MATCH(LARGE(Clean_Data!$K$2:$K$1466,14),Clean_Data!$K$2:$K$1466,0)) -> 253105 | F16: =INDEX(Clean_Data!$D$2:$D$1466,MATCH(LARGE(Clean_Data!$K$2:$K$1466,14),Clean_Data!$K$2:$K$1466,0)) -> 289 | G16: =LEFT(B16,22)&"…" -> SanDisk Cruzer Blade 3…
A17: 15 | B17: =INDEX(Clean_Data!$A$2:$A$1466,MATCH(LARGE(Clean_Data!$K$2:$K$1466,15),Clean_Data!$K$2:$K$1466,0)) -> SanDisk Extreme SD UHS I 64GB Card for 4K Video for DSLR and Mirrorless Cameras 170MB/s Read & 80MB/s Write | C17: =INDEX(Clean_Data!$B$2:$B$1466,MATCH(LARGE(Clean_Data!$K$2:$K$1466,15),Clean_Data!$K$2:$K$1466,0)) -> SanDisk | D17: =INDEX(Clean_Data!$G$2:$G$1466,MATCH(LARGE(Clean_Data!$K$2:$K$1466,15),Clean_Data!$K$2:$K$1466,0)) -> 4.5 | E17: =INDEX(Clean_Data!$H$2:$H$1466,MATCH(LARGE(Clean_Data!$K$2:$K$1466,15),Clean_Data!$K$2:$K$1466,0)) -> 205052 | F17: =INDEX(Clean_Data!$D$2:$D$1466,MATCH(LARGE(Clean_Data!$K$2:$K$1466,15),Clean_Data!$K$2:$K$1466,0)) -> 939 | G17: =LEFT(B17,22)&"…" -> SanDisk Extreme SD UHS…
A19: Top 15 Products by Discount %
A20: Rank | B20: Product Name | C20: Brand | D20: Discount % | E20: Actual Price | F20: Discounted Price
A21: 1 | B21: =INDEX(Clean_Data!$A$2:$A$1466,MATCH(LARGE(Clean_Data!$L$2:$L$1466,1),Clean_Data!$L$2:$L$1466,0)) -> rts [2 Pack] Mini USB C Type C Adapter Plug, Type C Female to USB A Male Charger Charging Cable Adapter Converter compatible for iPhone, Samsung S20 ultra/S21/S10/S8/S9/MacBook Pro iPad Silver | C21: =INDEX(Clean_Data!$B$2:$B$1466,MATCH(LARGE(Clean_Data!$L$2:$L$1466,1),Clean_Data!$L$2:$L$1466,0)) -> rts | D21: =INDEX(Clean_Data!$F$2:$F$1466,MATCH(LARGE(Clean_Data!$L$2:$L$1466,1),Clean_Data!$L$2:$L$1466,0)) -> 0.94 | E21: =INDEX(Clean_Data!$E$2:$E$1466,MATCH(LARGE(Clean_Data!$L$2:$L$1466,1),Clean_Data!$L$2:$L$1466,0)) -> 4999 | F21: =INDEX(Clean_Data!$D$2:$D$1466,MATCH(LARGE(Clean_Data!$L$2:$L$1466,1),Clean_Data!$L$2:$L$1466,0)) -> 294
A22: 2 | B22: =INDEX(Clean_Data!$A$2:$A$1466,MATCH(LARGE(Clean_Data!$L$2:$L$1466,2),Clean_Data!$L$2:$L$1466,0)) -> Fire-Boltt Ninja Call Pro Plus 1.83" Smart Watch with Bluetooth Calling, AI Voice Assistance, 100 Sports Modes IP67 Rating, 240*280 Pixel High Resolution | C22: =INDEX(Clean_Data!$B$2:$B$1466,MATCH(LARGE(Clean_Data!$L$2:$L$1466,2),Clean_Data!$L$2:$L$1466,0)) -> Fire-Boltt | D22: =INDEX(Clean_Data!$F$2:$F$1466,MATCH(LARGE(Clean_Data!$L$2:$L$1466,2),Clean_Data!$L$2:$L$1466,0)) -> 0.91 | E22: =INDEX(Clean_Data!$E$2:$E$1466,MATCH(LARGE(Clean_Data!$L$2:$L$1466,2),Clean_Data!$L$2:$L$1466,0)) -> 19999 | F22: =INDEX(Clean_Data!$D$2:$D$1466,MATCH(LARGE(Clean_Data!$L$2:$L$1466,2),Clean_Data!$L$2:$L$1466,0)) -> 1799
A23: 3 | B23: =INDEX(Clean_Data!$A$2:$A$1466,MATCH(LARGE(Clean_Data!$L$2:$L$1466,3),Clean_Data!$L$2:$L$1466,0)) -> Fire-Boltt Ninja Call Pro Plus 1.83" Smart Watch with Bluetooth Calling, AI Voice Assistance, 100 Sports Modes IP67 Rating, 240*280 Pixel High Resolution | C23: =INDEX(Clean_Data!$B$2:$B$1466,MATCH(LARGE(Clean_Data!$L$2:$L$1466,3),Clean_Data!$L$2:$L$1466,0)) -> Fire-Boltt | D23: =INDEX(Clean_Data!$F$2:$F$1466,MATCH(LARGE(Clean_Data!$L$2:$L$1466,3),Clean_Data!$L$2:$L$1466,0)) -> 0.91 | E23: =INDEX(Clean_Data!$E$2:$E$1466,MATCH(LARGE(Clean_Data!$L$2:$L$1466,3),Clean_Data!$L$2:$L$1466,0)) -> 19999 | F23: =INDEX(Clean_Data!$D$2:$D$1466,MATCH(LARGE(Clean_Data!$L$2:$L$1466,3),Clean_Data!$L$2:$L$1466,0)) -> 1799
A24: 4 | B24: =INDEX(Clean_Data!$A$2:$A$1466,MATCH(LARGE(Clean_Data!$L$2:$L$1466,4),Clean_Data!$L$2:$L$1466,0)) -> Fire-Boltt Ninja Call Pro Plus 1.83" Smart Watch with Bluetooth Calling, AI Voice Assistance, 100 Sports Modes IP67 Rating, 240*280 Pixel High Resolution | C24: =INDEX(Clean_Data!$B$2:$B$1466,MATCH(LARGE(Clean_Data!$L$2:$L$1466,4),Clean_Data!$L$2:$L$1466,0)) -> Fire-Boltt | D24: =INDEX(Clean_Data!$F$2:$F$1466,MATCH(LARGE(Clean_Data!$L$2:$L$1466,4),Clean_Data!$L$2:$L$1466,0)) -> 0.91 | E24: =INDEX(Clean_Data!$E$2:$E$1466,MATCH(LARGE(Clean_Data!$L$2:$L$1466,4),Clean_Data!$L$2:$L$1466,0)) -> 19999 | F24: =INDEX(Clean_Data!$D$2:$D$1466,MATCH(LARGE(Clean_Data!$L$2:$L$1466,4),Clean_Data!$L$2:$L$1466,0)) -> 1799
A25: 5 | B25: =INDEX(Clean_Data!$A$2:$A$1466,MATCH(LARGE(Clean_Data!$L$2:$L$1466,5),Clean_Data!$L$2:$L$1466,0)) -> Fire-Boltt Ninja Call Pro Plus 1.83" Smart Watch with Bluetooth Calling, AI Voice Assistance, 100 Sports Modes IP67 Rating, 240*280 Pixel High Resolution | C25: =INDEX(Clean_Data!$B$2:$B$1466,MATCH(LARGE(Clean_Data!$L$2:$L$1466,5),Clean_Data!$L$2:$L$1466,0)) -> Fire-Boltt | D25: =INDEX(Clean_Data!$F$2:$F$1466,MATCH(LARGE(Clean_Data!$L$2:$L$1466,5),Clean_Data!$L$2:$L$1466,0)) -> 0.91 | E25: =INDEX(Clean_Data!$E$2:$E$1466,MATCH(LARGE(Clean_Data!$L$2:$L$1466,5),Clean_Data!$L$2:$L$1466,0)) -> 19999 | F25: =INDEX(Clean_Data!$D$2:$D$1466,MATCH(LARGE(Clean_Data!$L$2:$L$1466,5),Clean_Data!$L$2:$L$1466,0)) -> 1799
A26: 6 | B26: =INDEX(Clean_Data!$A$2:$A$1466,MATCH(LARGE(Clean_Data!$L$2:$L$1466,6),Clean_Data!$L$2:$L$1466,0)) -> Fire-Boltt Ninja Call Pro Plus 1.83" Smart Watch with Bluetooth Calling, AI Voice Assistance, 100 Sports Modes IP67 Rating, 240*280 Pixel High Resolution | C26: =INDEX(Clean_Data!$B$2:$B$1466,MATCH(LARGE(Clean_Data!$L$2:$L$1466,6),Clean_Data!$L$2:$L$1466,0)) -> Fire-Boltt | D26: =INDEX(Clean_Data!$F$2:$F$1466,MATCH(LARGE(Clean_Data!$L$2:$L$1466,6),Clean_Data!$L$2:$L$1466,0)) -> 0.91 | E26: =INDEX(Clean_Data!$E$2:$E$1466,MATCH(LARGE(Clean_Data!$L$2:$L$1466,6),Clean_Data!$L$2:$L$1466,0)) -> 19999 | F26: =INDEX(Clean_Data!$D$2:$D$1466,MATCH(LARGE(Clean_Data!$L$2:$L$1466,6),Clean_Data!$L$2:$L$1466,0)) -> 1799
A27: 7 | B27: =INDEX(Clean_Data!$A$2:$A$1466,MATCH(LARGE(Clean_Data!$L$2:$L$1466,7),Clean_Data!$L$2:$L$1466,0)) -> beatXP Kitchen Scale Multipurpose Portable Electronic Digital Weighing Scale | Weight Machine With Back light LCD Display | White |10 kg | 2 Year Warranty | | C27: =INDEX(Clean_Data!$B$2:$B$1466,MATCH(LARGE(Clean_Data!$L$2:$L$1466,7),Clean_Data!$L$2:$L$1466,0)) -> beatXP | D27: =INDEX(Clean_Data!$F$2:$F$1466,MATCH(LARGE(Clean_Data!$L$2:$L$1466,7),Clean_Data!$L$2:$L$1466,0)) -> 0.9 | E27: =INDEX(Clean_Data!$E$2:$E$1466,MATCH(LARGE(Clean_Data!$L$2:$L$1466,7),Clean_Data!$L$2:$L$1466,0)) -> 1999 | F27: =INDEX(Clean_Data!$D$2:$D$1466,MATCH(LARGE(Clean_Data!$L$2:$L$1466,7),Clean_Data!$L$2:$L$1466,0)) -> 199
A28: 8 | B28: =INDEX(Clean_Data!$A$2:$A$1466,MATCH(LARGE(Clean_Data!$L$2:$L$1466,8),Clean_Data!$L$2:$L$1466,0)) -> Silicone Rubber Earbuds Tips, Eartips, Earpads, Earplugs, for Replacement in Earphones and Bluetooth Medium Size (10 Pcs Black) | C28: =INDEX(Clean_Data!$B$2:$B$1466,MATCH(LARGE(Clean_Data!$L$2:$L$1466,8),Clean_Data!$L$2:$L$1466,0)) -> Silicone | D28: =INDEX(Clean_Data!$F$2:$F$1466,MATCH(LARGE(Clean_Data!$L$2:$L$1466,8),Clean_Data!$L$2:$L$1466,0)) -> 0.9 | E28: =INDEX(Clean_Data!$E$2:$E$1466,MATCH(LARGE(Clean_Data!$L$2:$L$1466,8),Clean_Data!$L$2:$L$1466,0)) -> 999 | F28: =INDEX(Clean_Data!$D$2:$D$1466,MATCH(LARGE(Clean_Data!$L$2:$L$1466,8),Clean_Data!$L$2:$L$1466,0)) -> 99
A29: 9 | B29: =INDEX(Clean_Data!$A$2:$A$1466,MATCH(LARGE(Clean_Data!$L$2:$L$1466,9),Clean_Data!$L$2:$L$1466,0)) -> Sounce Spiral Charger Cable Protector Data Cable Saver Charging Cord Protective Cable Cover Headphone MacBook Laptop Earphone Cell Phone Set of 3 (Cable Protector (12 Units)) | C29: =INDEX(Clean_Data!$B$2:$B$1466,MATCH(LARGE(Clean_Data!$L$2:$L$1466,9),Clean_Data!$L$2:$L$1466,0)) -> Sounce | D29: =INDEX(Clean_Data!$F$2:$F$1466,MATCH(LARGE(Clean_Data!$L$2:$L$1466,9),Clean_Data!$L$2:$L$1466,0)) -> 0.9 | E29: =INDEX(Clean_Data!$E$2:$E$1466,MATCH(LARGE(Clean_Data!$L$2:$L$1466,9),Clean_Data!$L$2:$L$1466,0)) -> 999 | F29: =INDEX(Clean_Data!$D$2:$D$1466,MATCH(LARGE(Clean_Data!$L$2:$L$1466,9),Clean_Data!$L$2:$L$1466,0)) -> 99
A30: 10 | B30: =INDEX(Clean_Data!$A$2:$A$1466,MATCH(LARGE(Clean_Data!$L$2:$L$1466,10),Clean_Data!$L$2:$L$1466,0)) -> LAPSTER Spiral Charger Spiral Charger Cable Protectors for Wires Data Cable Saver Charging Cord Protective Cable Cover Set of 3 (12 Pieces) | C30: =INDEX(Clean_Data!$B$2:$B$1466,MATCH(LARGE(Clean_Data!$L$2:$L$1466,10),Clean_Data!$L$2:$L$1466,0)) -> LAPSTER | D30: =INDEX(Clean_Data!$F$2:$F$1466,MATCH(LARGE(Clean_Data!$L$2:$L$1466,10),Clean_Data!$L$2:$L$1466,0)) -> 0.9 | E30: =INDEX(Clean_Data!$E$2:$E$1466,MATCH(LARGE(Clean_Data!$L$2:$L$1466,10),Clean_Data!$L$2:$L$1466,0)) -> 999 | F30: =INDEX(Clean_Data!$D$2:$D$1466,MATCH(LARGE(Clean_Data!$L$2:$L$1466,10),Clean_Data!$L$2:$L$1466,0)) -> 99
A31: 11 | B31: =INDEX(Clean_Data!$A$2:$A$1466,MATCH(LARGE(Clean_Data!$L$2:$L$1466,11),Clean_Data!$L$2:$L$1466,0)) -> LAPSTER 12pcs Spiral Cable Protectors for Charger, Wires, Data Charger Cable Protector for Computers, Cell Phones etc.(Grey) | C31: =INDEX(Clean_Data!$B$2:$B$1466,MATCH(LARGE(Clean_Data!$L$2:$L$1466,11),Clean_Data!$L$2:$L$1466,0)) -> LAPSTER | D31: =INDEX(Clean_Data!$F$2:$F$1466,MATCH(LARGE(Clean_Data!$L$2:$L$1466,11),Clean_Data!$L$2:$L$1466,0)) -> 0.9 | E31: =INDEX(Clean_Data!$E$2:$E$1466,MATCH(LARGE(Clean_Data!$L$2:$L$1466,11),Clean_Data!$L$2:$L$1466,0)) -> 999 | F31: =INDEX(Clean_Data!$D$2:$D$1466,MATCH(LARGE(Clean_Data!$L$2:$L$1466,11),Clean_Data!$L$2:$L$1466,0)) -> 99
A32: 12 | B32: =INDEX(Clean_Data!$A$2:$A$1466,MATCH(LARGE(Clean_Data!$L$2:$L$1466,12),Clean_Data!$L$2:$L$1466,0)) -> Sounce Protective Case Cover Compatible Boat Xtend Overall Protective Case TPU HD Clear Ultra-Thin Cover with Unbreakable Screen Guard | C32: =INDEX(Clean_Data!$B$2:$B$1466,MATCH(LARGE(Clean_Data!$L$2:$L$1466,12),Clean_Data!$L$2:$L$1466,0)) -> Sounce | D32: =INDEX(Clean_Data!$F$2:$F$1466,MATCH(LARGE(Clean_Data!$L$2:$L$1466,12),Clean_Data!$L$2:$L$1466,0)) -> 0.9 | E32: =INDEX(Clean_Data!$E$2:$E$1466,MATCH(LARGE(Clean_Data!$L$2:$L$1466,12),Clean_Data!$L$2:$L$1466,0)) -> 1899 | F32: =INDEX(Clean_Data!$D$2:$D$1466,MATCH(LARGE(Clean_Data!$L$2:$L$1466,12),Clean_Data!$L$2:$L$1466,0)) -> 199
A33: 13 | B33: =INDEX(Clean_Data!$A$2:$A$1466,MATCH(LARGE(Clean_Data!$L$2:$L$1466,13),Clean_Data!$L$2:$L$1466,0)) -> Sounce Spiral Charger Cable Protector Data Cable Saver Charging Cord Protective Cable Cover Headphone MacBook Laptop Earphone Cell Phone Set of 3 (Cable Protector (12 Units)) | C33: =INDEX(Clean_Data!$B$2:$B$1466,MATCH(LARGE(Clean_Data!$L$2:$L$1466,13),Clean_Data!$L$2:$L$1466,0)) -> Sounce | D33: =INDEX(Clean_Data!$F$2:$F$1466,MATCH(LARGE(Clean_Data!$L$2:$L$1466,13),Clean_Data!$L$2:$L$1466,0)) -> 0.9 | E33: =INDEX(Clean_Data!$E$2:$E$1466,MATCH(LARGE(Clean_Data!$L$2:$L$1466,13),Clean_Data!$L$2:$L$1466,0)) -> 999 | F33: =INDEX(Clean_Data!$D$2:$D$1466,MATCH(LARGE(Clean_Data!$L$2:$L$1466,13),Clean_Data!$L$2:$L$1466,0)) -> 99
A34: 14 | B34: =INDEX(Clean_Data!$A$2:$A$1466,MATCH(LARGE(Clean_Data!$L$2:$L$1466,14),Clean_Data!$L$2:$L$1466,0)) -> Sounce Fast Phone Charging Cable & Data Sync USB Cable Compatible for iPhone 13, 12,11, X, 8, 7, 6, 5, iPad Air, Pro, Mini & iOS Devices | C34: =INDEX(Clean_Data!$B$2:$B$1466,MATCH(LARGE(Clean_Data!$L$2:$L$1466,14),Clean_Data!$L$2:$L$1466,0)) -> Sounce | D34: =INDEX(Clean_Data!$F$2:$F$1466,MATCH(LARGE(Clean_Data!$L$2:$L$1466,14),Clean_Data!$L$2:$L$1466,0)) -> 0.9 | E34: =INDEX(Clean_Data!$E$2:$E$1466,MATCH(LARGE(Clean_Data!$L$2:$L$1466,14),Clean_Data!$L$2:$L$1466,0)) -> 1899 | F34: =INDEX(Clean_Data!$D$2:$D$1466,MATCH(LARGE(Clean_Data!$L$2:$L$1466,14),Clean_Data!$L$2:$L$1466,0)) -> 199
A35: 15 | B35: =INDEX(Clean_Data!$A$2:$A$1466,MATCH(LARGE(Clean_Data!$L$2:$L$1466,15),Clean_Data!$L$2:$L$1466,0)) -> pTron Solero M241 2.4A Micro USB Data & Charging Cable, Made in India, 480Mbps Data Sync, Durable 1-Meter Long USB Cable for Micro USB Devices (White) | C35: =INDEX(Clean_Data!$B$2:$B$1466,MATCH(LARGE(Clean_Data!$L$2:$L$1466,15),Clean_Data!$L$2:$L$1466,0)) -> pTron | D35: =INDEX(Clean_Data!$F$2:$F$1466,MATCH(LARGE(Clean_Data!$L$2:$L$1466,15),Clean_Data!$L$2:$L$1466,0)) -> 0.89 | E35: =INDEX(Clean_Data!$E$2:$E$1466,MATCH(LARGE(Clean_Data!$L$2:$L$1466,15),Clean_Data!$L$2:$L$1466,0)) -> 800 | F35: =INDEX(Clean_Data!$D$2:$D$1466,MATCH(LARGE(Clean_Data!$L$2:$L$1466,15),Clean_Data!$L$2:$L$1466,0)) -> 89

Sheet Dashboard
B2: Amazon Sales Dashboard
B3: 1,465 products | 290 tracked listings across top 10 brands | 9 categories
B5: Total Products | F5: Avg Rating | J5: Avg Discount % | N5: Total Reviews | R5: Avg Savings
B6: =COUNTA(Clean_Data!A2:A1466) -> 1465 | F6: =AVERAGE(Clean_Data!G2:G1466) -> 4.0965847 | J6: =AVERAGE(Clean_Data!F2:F1466) -> 0.47691468 | N6: =SUM(Clean_Data!H2:H1466) -> 26766377 | R6: =AVERAGE(Clean_Data!I2:I1466) -> 2319.6798
